Workbook

Sheet Metales puros
C1: Au | D1: Yakubovsky-4nm | H1: Au | I1: McPeak et al 20015 | M1: Ag | N1: McPeak et al. 2015 | R1: Al | S1: McPeak et al. 2015 | W1: Cu | X1: McPeak et al. 2015 | AB1: Pt (Platinum) | AC1: Werner et al. 2009 | AG1: Zn (Zinc) | AH1: Werner et al. 2009 | AL1: Fe (Hierro) | AM1: Werner et al. 2009
A2: wl | C2: n | D2: k | F2: wl | H2: n | I2: k | K2: wl | M2: n | N2: k | P2: wl | R2: n | S2: k | U2: wl | W2: n | X2: k | Z2: wl | AB2: n | AC2: k | AE2: wl | AG2: n | AH2: k | AJ2: wl | AL2: n | AM2: k
A3: 0.3 | B3: =A3*1000 -> 300 | C3: 1.536 | D3: 1.286 | F3: 0.3 | G3: =F3*1000 -> 300 | H3: 1.6998387 | I3: 1.9731578 | K3: 0.3 | L3: =K3*1000 -> 300 | M3: 1.6468573 | N3: 0.97233683 | P3: 0.15 | Q3: =P3*1000 -> 150 | R3: 0.095390828 | S3: 1.2836664 | U3: 0.3 | V3: =U3*1000 -> 300 | W3: 1.34746 | X3: 1.6794191 | Z3: 0.017586 | AA3: =Z3*1000 -> 17.586 | AB3: 0.8718 | AC3: 0.1182 | AE3: 0.017586 | AF3: =AE3*1000 -> 17.586 | AG3: 0.9522 | AH3: 0.0688 | AJ3: 0.017586 | AK3: =AJ3*1000 -> 17.586 | AL3: 0.8555 | AM3: 0.1262
A4: 0.31 | B4: =A4*1000 -> 310 | C4: 1.341 | D4: 1.461 | F4: 0.31 | G4: =F4*1000 -> 310 | H4: 1.7469487 | I4: 1.9744999 | K4: 0.31 | L4: =K4*1000 -> 310 | M4: 1.4556297 | N4: 0.57250137 | P4: 0.155 | Q4: =P4*1000 -> 155 | R4: 0.095510386 | S4: 1.3373938 | U4: 0.31 | V4: =U4*1000 -> 310 | W4: 1.3214732 | X4: 1.7401412 | Z4: 0.017712 | AA4: =Z4*1000 -> 17.712 | AB4: 0.8709 | AC4: 0.12 | AE4: 0.017712 | AF4: =AE4*1000 -> 17.712 | AG4: 0.9523 | AH4: 0.0693 | AJ4: 0.017712 | AK4: =AJ4*1000 -> 17.712 | AL4: 0.8552 | AM4: 0.1316
A5: 0.32 | B5: =A5*1000 -> 320 | C5: 1.367 | D5: 1.643 | F5: 0.32 | G5: =F5*1000 -> 320 | H5: 1.782941 | I5: 1.9597956 | K5: 0.32 | L5: =K5*1000 -> 320 | M5: 0.92005863 | N5: 0.33153866 | P5: 0.16 | Q5: =P5*1000 -> 160 | R5: 0.09903925 | S5: 1.4029286 | U5: 0.32 | V5: =U5*1000 -> 320 | W5: 1.3018969 | X5: 1.7815543 | Z5: 0.017839 | AA5: =Z5*1000 -> 17.839 | AB5: 0.8699 | AC5: 0.1213 | AE5: 0.017839 | AF5: =AE5*1000 -> 17.839 | AG5: 0.9518 | AH5: 0.0704 | AJ5: 0.017839 | AK5: =AJ5*1000 -> 17.839 | AL5: 0.8543 | AM5: 0.137
A6: 0.33 | B6: =A6*1000 -> 330 | C6: 1.405 | D6: 1.829 | F6: 0.33 | G6: =F6*1000 -> 330 | H6: 1.804653 | I6: 1.9319504 | K6: 0.33 | L6: =K6*1000 -> 330 | M6: 0.233798 | N6: 0.58544129 | P6: 0.165 | Q6: =P6*1000 -> 165 | R6: 0.098692838 | S6: 1.4661652 | U6: 0.33 | V6: =U6*1000 -> 330 | W6: 1.2788153 | X6: 1.8162513 | Z6: 0.017969 | AA6: =Z6*1000 -> 17.969 | AB6: 0.8695 | AC6: 0.1225 | AE6: 0.017969 | AF6: =AE6*1000 -> 17.969 | AG6: 0.9519 | AH6: 0.0709 | AJ6: 0.017969 | AK6: =AJ6*1000 -> 17.969 | AL6: 0.8546 | AM6: 0.1428
A7: 0.34 | B7: =A7*1000 -> 340 | C7: 1.648 | D7: 2.026 | F7: 0.34 | G7: =F7*1000 -> 340 | H7: 1.8046213 | I7: 1.8967968 | K7: 0.34 | L7: =K7*1000 -> 340 | M7: 0.10389312 | N7: 1.0520427 | P7: 0.17 | Q7: =P7*1000 -> 170 | R7: 0.10085021 | S7: 1.53257 | U7: 0.34 | V7: =U7*1000 -> 340 | W7: 1.2578561 | X7: 1.8575257 | Z7: 0.0181 | AA7: =Z7*1000 -> 18.1 | AB7: 0.8685 | AC7: 0.1238 | AE7: 0.0181 | AF7: =AE7*1000 -> 18.1 | AG7: 0.9514 | AH7: 0.072 | AJ7: 0.0181 | AK7: =AJ7*1000 -> 18.1 | AL7: 0.8545 | AM7: 0.1486
A8: 0.35 | B8: =A8*1000 -> 350 | C8: 2.103 | D8: 1.577 | F8: 0.35 | G8: =F8*1000 -> 350 | H8: 1.7637124 | I8: 1.8706848 | K8: 0.35 | L8: =K8*1000 -> 350 | M8: 0.07599858 | N8: 1.3268669 | P8: 0.175 | Q8: =P8*1000 -> 175 | R8: 0.1069563 | S8: 1.5965399 | U8: 0.35 | V8: =U8*1000 -> 350 | W8: 1.2297144 | X8: 1.8959687 | Z8: 0.018233 | AA8: =Z8*1000 -> 18.233 | AB8: 0.8675 | AC8: 0.1251 | AE8: 0.018233 | AF8: =AE8*1000 -> 18.233 | AG8: 0.9515 | AH8: 0.0725 | AJ8: 0.018233 | AK8: =AJ8*1000 -> 18.233 | AL8: 0.8555 | AM8: 0.1543
A9: 0.36 | B9: =A9*1000 -> 360 | C9: 2.1 | D9: 1.447 | F9: 0.36 | G9: =F9*1000 -> 360 | H9: 1.7134349 | I9: 1.8876703 | K9: 0.36 | L9: =K9*1000 -> 360 | M9: 0.063180003 | N9: 1.5330009 | P9: 0.18 | Q9: =P9*1000 -> 180 | R9: 0.099715746 | S9: 1.657662 | U9: 0.36 | V9: =U9*1000 -> 360 | W9: 1.2057938 | X9: 1.9411694 | Z9: 0.018368 | AA9: =Z9*1000 -> 18.368 | AB9: 0.8661 | AC9: 0.127 | AE9: 0.018368 | AF9: =AE9*1000 -> 18.368 | AG9: 0.951 | AH9: 0.0736 | AJ9: 0.018368 | AK9: =AJ9*1000 -> 18.368 | AL9: 0.8566 | AM9: 0.1605
A10: 0.37 | B10: =A10*1000 -> 370 | C10: 2.042 | D10: 1.346 | F10: 0.37 | G10: =F10*1000 -> 370 | H10: 1.6892021 | I10: 1.9220909 | K10: 0.37 | L10: =K10*1000 -> 370 | M10: 0.056279242 | N10: 1.708001 | P10: 0.185 | Q10: =P10*1000 -> 185 | R10: 0.10831611 | S10: 1.734368 | U10: 0.37 | V10: =U10*1000 -> 370 | W10: 1.1831341 | X10: 1.9932652 | Z10: 0.018505 | AA10: =Z10*1000 -> 18.505 | AB10: 0.8651 | AC10: 0.1283 | AE10: 0.018505 | AF10: =AE10*1000 -> 18.505 | AG10: 0.951 | AH10: 0.0741 | AJ10: 0.018505 | AK10: =AJ10*1000 -> 18.505 | AL10: 0.8582 | AM10: 0.166
A11: 0.38 | B11: =A11*1000 -> 380 | C11: 1.958 | D11: 1.315 | F11: 0.38 | G11: =F11*1000 -> 380 | H11: 1.6780591 | I11: 1.948382 | K11: 0.38 | L11: =K11*1000 -> 380 | M11: 0.050752406 | N11: 1.8587296 | P11: 0.19 | Q11: =P11*1000 -> 190 | R11: 0.10656777 | S11: 1.7911607 | U11: 0.38 | V11: =U11*1000 -> 380 | W11: 1.1657749 | X11: 2.0463213 | Z11: 0.018644 | AA11: =Z11*1000 -> 18.644 | AB11: 0.8636 | AC11: 0.1297 | AE11: 0.018644 | AF11: =AE11*1000 -> 18.644 | AG11: 0.9506 | AH11: 0.0752 | AJ11: 0.018644 | AK11: =AJ11*1000 -> 18.644 | AL11: 0.8605 | AM11: 0.1714
A12: 0.39 | B12: =A12*1000 -> 390 | C12: 1.917 | D12: 1.286 | F12: 0.39 | G12: =F12*1000 -> 390 | H12: 1.6725042 | I12: 1.9665122 | K12: 0.39 | L12: =K12*1000 -> 390 | M12: 0.048660415 | N12: 1.9954618 | P12: 0.195 | Q12: =P12*1000 -> 195 | R12: 0.11151327 | S12: 1.8534118 | U12: 0.39 | V12: =U12*1000 -> 390 | W12: 1.1399296 | X12: 2.0901291 | Z12: 0.018785 | AA12: =Z12*1000 -> 18.785 | AB12: 0.8621 | AC12: 0.1311 | AE12: 0.018785 | AF12: =AE12*1000 -> 18.785 | AG12: 0.9507 | AH12: 0.0763 | AJ12: 0.018785 | AK12: =AJ12*1000 -> 18.785 | AL12: 0.8633 | AM12: 0.1767
A13: 0.4 | B13: =A13*1000 -> 400 | C13: 1.871 | D13: 1.232 | F13: 0.4 | G13: =F13*1000 -> 400 | H13: 1.6656161 | I13: 1.9739243 | K13: 0.4 | L13: =K13*1000 -> 400 | M13: 0.04572895 | N13: 2.122944 | P13: 0.2 | Q13: =P13*1000 -> 200 | R13: 0.11080337 | S13: 1.9086061 | U13: 0.4 | V13: =U13*1000 -> 400 | W13: 1.119339 | X13: 2.1422464 | Z13: 0.018929 | AA13: =Z13*1000 -> 18.929 | AB13: 0.8606 | AC13: 0.1325 | AE13: 0.018929 | AF13: =AE13*1000 -> 18.929 | AG13: 0.9502 | AH13: 0.0768 | AJ13: 0.018929 | AK13: =AJ13*1000 -> 18.929 | AL13: 0.8666 | AM13: 0.1817
A14: 0.41 | B14: =A14*1000 -> 410 | C14: 1.795 | D14: 1.158 | F14: 0.41 | G14: =F14*1000 -> 410 | H14: 1.6539111 | I14: 1.9752271 | K14: 0.41 | L14: =K14*1000 -> 410 | M14: 0.04451952 | N14: 2.2418256 | P14: 0.205 | Q14: =P14*1000 -> 205 | R14: 0.11158733 | S14: 1.969937 | U14: 0.41 | V14: =U14*1000 -> 410 | W14: 1.0976615 | X14: 2.1934814 | Z14: 0.019074 | AA14: =Z14*1000 -> 19.074 | AB14: 0.8591 | AC14: 0.1344 | AE14: 0.019074 | AF14: =AE14*1000 -> 19.074 | AG14: 0.9498 | AH14: 0.0779 | AJ14: 0.019074 | AK14: =AJ14*1000 -> 19.074 | AL14: 0.8704 | AM14: 0.1861
... A143: 1.7 | B143: =A143*1000 -> 1700 | C143: 0.982 | D143: 9.637 | F143: 1.7 | G143: =F143*1000 -> 1700 | H143: 0.31648184 | I143: 12.370536 | K143: 1.7 | L143: =K143*1000 -> 1700 | M143: 0.19853159 | N143: 12.70352 | P143: 0.85 | Q143: =P143*1000 -> 850 | R143: 2.2048986 | S143: 7.1880858 | U143: 1.7 | V143: =U143*1000 -> 1700 | W143: 0.25589485 | X143: 12.026034 | Z143: 0.450852 | AA143: =Z143*1000 -> 450.852 | AB143: 0.6273 | AC143: 3.7605 | AE143: 0.450852 | AF143: =AE143*1000 -> 450.852 | AG143: 0.6794 | AH143: 4.0209 | AJ143: 0.450852 | AK143: =AJ143*1000 -> 450.852 | AL143: 1.0197 | AM143: 4.4072
A144: 1.71 | B144: =A144*1000 -> 1710 | C144: 0.99 | D144: 9.696 | P144: 0.855 | Q144: =P144*1000 -> 855 | R144: 2.1481114 | S144: 7.1777004 | Z144: 0.495937 | AA144: =Z144*1000 -> 495.937 | AB144: 0.5124 | AC144: 4.3965 | AE144: 0.495937 | AF144: =AE144*1000 -> 495.937 | AG144: 0.7858 | AH144: 4.4636 | AJ144: 0.495937 | AK144: =AJ144*1000 -> 495.937 | AL144: 1.0666 | AM144: 5.0863
A145: 1.72 | B145: =A145*1000 -> 1720 | C145: 0.998 | D145: 9.761 | P145: 0.86 | Q145: =P145*1000 -> 860 | R145: 2.0927188 | S145: 7.181328 | Z145: 0.551041 | AA145: =Z145*1000 -> 551.041 | AB145: 0.4643 | AC145: 5.121 | AE145: 0.551041 | AF145: =AE145*1000 -> 551.041 | AG145: 0.9322 | AH145: 4.985 | AJ145: 0.551041 | AK145: =AJ145*1000 -> 551.041 | AL145: 1.2276 | AM145: 5.9541
A146: 1.73 | B146: =A146*1000 -> 1730 | C146: 1.004 | D146: 9.814 | P146: 0.865 | Q146: =P146*1000 -> 865 | R146: 2.0312772 | S146: 7.1846424 | Z146: 0.619921 | AA146: =Z146*1000 -> 619.921 | AB146: 0.4611 | AC146: 5.9757 | AE146: 0.619921 | AF146: =AE146*1000 -> 619.921 | AG146: 1.1356 | AH146: 5.6116 | AJ146: 0.619921 | AK146: =AJ146*1000 -> 619.921 | AL146: 1.5753 | AM146: 7.0964
A147: 1.74 | B147: =A147*1000 -> 1740 | C147: 1.008 | D147: 9.869 | P147: 0.87 | Q147: =P147*1000 -> 870 | R147: 1.973569 | S147: 7.198887 | Z147: 0.708481 | AA147: =Z147*1000 -> 708.481 | AB147: 0.5013 | AC147: 7.0273 | AE147: 0.708481 | AF147: =AE147*1000 -> 708.481 | AG147: 1.4247 | AH147: 6.3811 | AJ147: 0.708481 | AK147: =AJ147*1000 -> 708.481 | AL147: 2.3096 | AM147: 8.6751
A148: 1.75 | B148: =A148*1000 -> 1750 | C148: 1.017 | D148: 9.929 | P148: 0.875 | Q148: =P148*1000 -> 875 | R148: 1.9154924 | S148: 7.2182485 | Z148: 0.826561 | AA148: =Z148*1000 -> 826.561 | AB148: 0.5979 | AC148: 8.3824 | AE148: 0.826561 | AF148: =AE148*1000 -> 826.561 | AG148: 1.8489 | AH148: 7.3486 | AJ148: 0.826561 | AK148: =AJ148*1000 -> 826.561 | AL148: 4.0769 | AM148: 10.9173
A149: 1.76 | B149: =A149*1000 -> 1760 | C149: 1.023 | D149: 9.988 | P149: 0.88 | Q149: =P149*1000 -> 880 | R149: 1.8549961 | S149: 7.2434115 | Z149: 0.991874 | AA149: =Z149*1000 -> 991.874 | AB149: 0.787 | AC149: 10.2266 | AE149: 0.991874 | AF149: =AE149*1000 -> 991.874 | AG149: 2.4976 | AH149: 8.5981 | AJ149: 0.991874 | AK149: =AJ149*1000 -> 991.874 | AL149: 9.0305 | AM149: 12.9363
A150: 1.77 | B150: =A150*1000 -> 1770 | C150: 1.03 | D150: 10.046 | P150: 0.885 | Q150: =P150*1000 -> 885 | R150: 1.8025647 | S150: 7.27408 | Z150: 1.239842 | AA150: =Z150*1000 -> 1239.842 | AB150: 1.1594 | AC150: 12.9215 | AE150: 1.239842 | AF150: =AE150*1000 -> 1239.842 | AG150: 3.5417 | AH150: 10.2617 | AJ150: 1.239842 | AK150: =AJ150*1000 -> 1239.842 | AL150: 14.9781 | AM150: 8.1082
A151: 1.78 | B151: =A151*1000 -> 1780 | C151: 1.037 | D151: 10.104 | P151: 0.89 | Q151: =P151*1000 -> 890 | R151: 1.7501204 | S151: 7.3097826 | Z151: 1.653123 | AA151: =Z151*1000 -> 1653.123 | AB151: 1.9756 | AC151: 17.2802 | AE151: 1.653123 | AF151: =AE151*1000 -> 1653.123 | AG151: 5.3318 | AH151: 12.5605 | AJ151: 1.653123 | AK151: =AJ151*1000 -> 1653.123 | AL151: 14.0346 | AM151: 3.2184
A152: 1.79 | B152: =A152*1000 -> 1790 | C152: 1.044 | D152: 10.161 | P152: 0.895 | Q152: =P152*1000 -> 895 | R152: 1.6946717 | S152: 7.3500961 | Z152: 2.479684 | AA152: =Z152*1000 -> 2479.684 | AB152: 4.2255 | AC152: 25.5617 | AE152: 2.479684 | AF152: =AE152*1000 -> 2479.684 | AG152: 8.6709 | AH152: 15.947 | AJ152: 2.479684 | AK152: =AJ152*1000 -> 2479.684 | AL152: 12.6146 | AM152: 1.4154
A153: 1.8 | B153: =A153*1000 -> 1800 | C153: 1.052 | D153: 10.221 | P153: 0.9 | Q153: =P153*1000 -> 900 | R153: 1.6471561 | S153: 7.3930456
A154: 1.81 | B154: =A154*1000 -> 1810 | C154: 1.058 | D154: 10.279 | P154: 0.905 | Q154: =P154*1000 -> 905 | R154: 1.6023995 | S154: 7.439468
A155: 1.82 | B155: =A155*1000 -> 1820 | C155: 1.064 | D155: 10.337 | P155: 0.91 | Q155: =P155*1000 -> 910 | R155: 1.5571882 | S155: 7.489782
A156: 1.83 | B156: =A156*1000 -> 1830 | C156: 1.071 | D156: 10.396 | P156: 0.915 | Q156: =P156*1000 -> 915 | R156: 1.5168379 | S156: 7.5426651
A157: 1.84 | B157: =A157*1000 -> 1840 | C157: 1.08 | D157: 10.454 | P157: 0.92 | Q157: =P157*1000 -> 920 | R157: 1.4835455 | S157: 7.5926219
A158: 1.85 | B158: =A158*1000 -> 1850 | C158: 1.089 | D158: 10.514 | P158: 0.925 | Q158: =P158*1000 -> 925 | R158: 1.4472305 | S158: 7.6477105
A159: 1.86 | B159: =A159*1000 -> 1860 | C159: 1.096 | D159: 10.567 | P159: 0.93 | Q159: =P159*1000 -> 930 | R159: 1.4152138 | S159: 7.7034298
A160: 1.87 | B160: =A160*1000 -> 1870 | C160: 1.105 | D160: 10.633 | P160: 0.935 | Q160: =P160*1000 -> 935 | R160: 1.3854333 | S160: 7.7560573
A161: 1.88 | B161: =A161*1000 -> 1880 | C161: 1.114 | D161: 10.69 | P161: 0.94 | Q161: =P161*1000 -> 940 | R161: 1.3555899 | S161: 7.8124659
A162: 1.89 | B162: =A162*1000 -> 1890 | C162: 1.119 | D162: 10.74 | P162: 0.945 | Q162: =P162*1000 -> 945 | R162: 1.325885 | S162: 7.8721008
A163: 1.9 | B163: =A163*1000 -> 1900 | C163: 1.134 | D163: 10.818 | P163: 0.95 | Q163: =P163*1000 -> 950 | R163: 1.3021645 | S163: 7.928722
A164: 1.91 | B164: =A164*1000 -> 1910 | C164: 1.145 | D164: 10.881 | P164: 0.955 | Q164: =P164*1000 -> 955 | R164: 1.2802888 | S164: 7.9853077
... A299: 3.26 | B299: =A299*1000 -> 3260 | C299: 2.762 | D299: 18.627 | P299: 1.7 | Q299: =P299*1000 -> 1700 | R299: 1.5840185 | S299: 15.556321
A300: 3.27 | B300: =A300*1000 -> 3270 | C300: 2.787 | D300: 18.682
A301: 3.28 | B301: =A301*1000 -> 3280 | C301: 2.793 | D301: 18.784
A302: 3.29 | B302: =A302*1000 -> 3290 | C302: 2.832 | D302: 18.821
...

Sheet USO
A1: lambda | B1: nAu | C1: kAu | D1: nAg | E1: kAg | F1: nAl | G1: kAl | H1: nCu | I1: kCu | J1: nPt | K1: kPt | L1: nZn | M1: kZn | N1: nFe | O1: kFe
A2: ='Metales puros'!B3 -> 300 | B2: ='Metales puros'!H3 -> 1.6998387 | C2: ='Metales puros'!I3 -> 1.9731578 | D2: ='Metales puros'!M3 -> 1.6468573 | E2: ='Metales puros'!N3 -> 0.97233683 | F2: ='Metales puros'!R3 -> 0.095390828 | G2: ='Metales puros'!S3 -> 1.2836664 | H2: ='Metales puros'!W3 -> 1.34746 | I2: ='Metales puros'!X3 -> 1.6794191 | J2: ='Metales puros'!AB3 -> 0.8718 | K2: ='Metales puros'!AC3 -> 0.1182 | L2: ='Metales puros'!AG3 -> 0.9522 | M2: ='Metales puros'!AH3 -> 0.0688 | N2: ='Metales puros'!AL3 -> 0.8555 | O2: ='Metales puros'!AM3 -> 0.1262
A3: ='Metales puros'!B4 -> 310 | B3: ='Metales puros'!H4 -> 1.7469487 | C3: ='Metales puros'!I4 -> 1.9744999 | D3: ='Metales puros'!M4 -> 1.4556297 | E3: ='Metales puros'!N4 -> 0.57250137 | F3: ='Metales puros'!R4 -> 0.095510386 | G3: ='Metales puros'!S4 -> 1.3373938 | H3: ='Metales puros'!W4 -> 1.3214732 | I3: ='Metales puros'!X4 -> 1.7401412 | J3: ='Metales puros'!AB4 -> 0.8709 | K3: ='Metales puros'!AC4 -> 0.12 | L3: ='Metales puros'!AG4 -> 0.9523 | M3: ='Metales puros'!AH4 -> 0.0693 | N3: ='Metales puros'!AL4 -> 0.8552 | O3: ='Metales puros'!AM4 -> 0.1316
A4: ='Metales puros'!B5 -> 320 | B4: ='Metales puros'!H5 -> 1.782941 | C4: ='Metales puros'!I5 -> 1.9597956 | D4: ='Metales puros'!M5 -> 0.92005863 | E4: ='Metales puros'!N5 -> 0.33153866 | F4: ='Metales puros'!R5 -> 0.09903925 | G4: ='Metales puros'!S5 -> 1.4029286 | H4: ='Metales puros'!W5 -> 1.3018969 | I4: ='Metales puros'!X5 -> 1.7815543 | J4: ='Metales puros'!AB5 -> 0.8699 | K4: ='Metales puros'!AC5 -> 0.1213 | L4: ='Metales puros'!AG5 -> 0.9518 | M4: ='Metales puros'!AH5 -> 0.0704 | N4: ='Metales puros'!AL5 -> 0.8543 | O4: ='Metales puros'!AM5 -> 0.137
A5: ='Metales puros'!B6 -> 330 | B5: ='Metales puros'!H6 -> 1.804653 | C5: ='Metales puros'!I6 -> 1.9319504 | D5: ='Metales puros'!M6 -> 0.233798 | E5: ='Metales puros'!N6 -> 0.58544129 | F5: ='Metales puros'!R6 -> 0.098692838 | G5: ='Metales puros'!S6 -> 1.4661652 | H5: ='Metales puros'!W6 -> 1.2788153 | I5: ='Metales puros'!X6 -> 1.8162513 | J5: ='Metales puros'!AB6 -> 0.8695 | K5: ='Metales puros'!AC6 -> 0.1225 | L5: ='Metales puros'!AG6 -> 0.9519 | M5: ='Metales puros'!AH6 -> 0.0709 | N5: ='Metales puros'!AL6 -> 0.8546 | O5: ='Metales puros'!AM6 -> 0.1428
A6: ='Metales puros'!B7 -> 340 | B6: ='Metales puros'!H7 -> 1.8046213 | C6: ='Metales puros'!I7 -> 1.8967968 | D6: ='Metales puros'!M7 -> 0.10389312 | E6: ='Metales puros'!N7 -> 1.0520427 | F6: ='Metales puros'!R7 -> 0.10085021 | G6: ='Metales puros'!S7 -> 1.53257 | H6: ='Metales puros'!W7 -> 1.2578561 | I6: ='Metales puros'!X7 -> 1.8575257 | J6: ='Metales puros'!AB7 -> 0.8685 | K6: ='Metales puros'!AC7 -> 0.1238 | L6: ='Metales puros'!AG7 -> 0.9514 | M6: ='Metales puros'!AH7 -> 0.072 | N6: ='Metales puros'!AL7 -> 0.8545 | O6: ='Metales puros'!AM7 -> 0.1486
A7: ='Metales puros'!B8 -> 350 | B7: ='Metales puros'!H8 -> 1.7637124 | C7: ='Metales puros'!I8 -> 1.8706848 | D7: ='Metales puros'!M8 -> 0.07599858 | E7: ='Metales puros'!N8 -> 1.3268669 | F7: ='Metales puros'!R8 -> 0.1069563 | G7: ='Metales puros'!S8 -> 1.5965399 | H7: ='Metales puros'!W8 -> 1.2297144 | I7: ='Metales puros'!X8 -> 1.8959687 | J7: ='Metales puros'!AB8 -> 0.8675 | K7: ='Metales puros'!AC8 -> 0.1251 | L7: ='Metales puros'!AG8 -> 0.9515 | M7: ='Metales puros'!AH8 -> 0.0725 | N7: ='Metales puros'!AL8 -> 0.8555 | O7: ='Metales puros'!AM8 -> 0.1543
A8: ='Metales puros'!B9 -> 360 | B8: ='Metales puros'!H9 -> 1.7134349 | C8: ='Metales puros'!I9 -> 1.8876703 | D8: ='Metales puros'!M9 -> 0.063180003 | E8: ='Metales puros'!N9 -> 1.5330009 | F8: ='Metales puros'!R9 -> 0.099715746 | G8: ='Metales puros'!S9 -> 1.657662 | H8: ='Metales puros'!W9 -> 1.2057938 | I8: ='Metales puros'!X9 -> 1.9411694 | J8: ='Metales puros'!AB9 -> 0.8661 | K8: ='Metales puros'!AC9 -> 0.127 | L8: ='Metales puros'!AG9 -> 0.951 | M8: ='Metales puros'!AH9 -> 0.0736 | N8: ='Metales puros'!AL9 -> 0.8566 | O8: ='Metales puros'!AM9 -> 0.1605
A9: ='Metales puros'!B10 -> 370 | B9: ='Metales puros'!H10 -> 1.6892021 | C9: ='Metales puros'!I10 -> 1.9220909 | D9: ='Metales puros'!M10 -> 0.056279242 | E9: ='Metales puros'!N10 -> 1.708001 | F9: ='Metales puros'!R10 -> 0.10831611 | G9: ='Metales puros'!S10 -> 1.734368 | H9: ='Metales puros'!W10 -> 1.1831341 | I9: ='Metales puros'!X10 -> 1.9932652 | J9: ='Metales puros'!AB10 -> 0.8651 | K9: ='Metales puros'!AC10 -> 0.1283 | L9: ='Metales puros'!AG10 -> 0.951 | M9: ='Metales puros'!AH10 -> 0.0741 | N9: ='Metales puros'!AL10 -> 0.8582 | O9: ='Metales puros'!AM10 -> 0.166
A10: ='Metales puros'!B11 -> 380 | B10: ='Metales puros'!H11 -> 1.6780591 | C10: ='Metales puros'!I11 -> 1.948382 | D10: ='Metales puros'!M11 -> 0.050752406 | E10: ='Metales puros'!N11 -> 1.8587296 | F10: ='Metales puros'!R11 -> 0.10656777 | G10: ='Metales puros'!S11 -> 1.7911607 | H10: ='Metales puros'!W11 -> 1.1657749 | I10: ='Metales puros'!X11 -> 2.0463213 | J10: ='Metales puros'!AB11 -> 0.8636 | K10: ='Metales puros'!AC11 -> 0.1297 | L10: ='Metales puros'!AG11 -> 0.9506 | M10: ='Metales puros'!AH11 -> 0.0752 | N10: ='Metales puros'!AL11 -> 0.8605 | O10: ='Metales puros'!AM11 -> 0.1714
A11: ='Metales puros'!B12 -> 390 | B11: ='Metales puros'!H12 -> 1.6725042 | C11: ='Metales puros'!I12 -> 1.9665122 | D11: ='Metales puros'!M12 -> 0.048660415 | E11: ='Metales puros'!N12 -> 1.9954618 | F11: ='Metales puros'!R12 -> 0.11151327 | G11: ='Metales puros'!S12 -> 1.8534118 | H11: ='Metales puros'!W12 -> 1.1399296 | I11: ='Metales puros'!X12 -> 2.0901291 | J11: ='Metales puros'!AB12 -> 0.8621 | K11: ='Metales puros'!AC12 -> 0.1311 | L11: ='Metales puros'!AG12 -> 0.9507 | M11: ='Metales puros'!AH12 -> 0.0763 | N11: ='Metales puros'!AL12 -> 0.8633 | O11: ='Metales puros'!AM12 -> 0.1767
A12: ='Metales puros'!B13 -> 400 | B12: ='Metales puros'!H13 -> 1.6656161 | C12: ='Metales puros'!I13 -> 1.9739243 | D12: ='Metales puros'!M13 -> 0.04572895 | E12: ='Metales puros'!N13 -> 2.122944 | F12: ='Metales puros'!R13 -> 0.11080337 | G12: ='Metales puros'!S13 -> 1.9086061 | H12: ='Metales puros'!W13 -> 1.119339 | I12: ='Metales puros'!X13 -> 2.1422464 | J12: ='Metales puros'!AB13 -> 0.8606 | K12: ='Metales puros'!AC13 -> 0.1325 | L12: ='Metales puros'!AG13 -> 0.9502 | M12: ='Metales puros'!AH13 -> 0.0768 | N12: ='Metales puros'!AL13 -> 0.8666 | O12: ='Metales puros'!AM13 -> 0.1817
A13: ='Metales puros'!B14 -> 410 | B13: ='Metales puros'!H14 -> 1.6539111 | C13: ='Metales puros'!I14 -> 1.9752271 | D13: ='Metales puros'!M14 -> 0.04451952 | E13: ='Metales puros'!N14 -> 2.2418256 | F13: ='Metales puros'!R14 -> 0.11158733 | G13: ='Metales puros'!S14 -> 1.969937 | H13: ='Metales puros'!W14 -> 1.0976615 | I13: ='Metales puros'!X14 -> 2.1934814 | J13: ='Metales puros'!AB14 -> 0.8591 | K13: ='Metales puros'!AC14 -> 0.1344 | L13: ='Metales puros'!AG14 -> 0.9498 | M13: ='Metales puros'!AH14 -> 0.0779 | N13: ='Metales puros'!AL14 -> 0.8704 | O13: ='Metales puros'!AM14 -> 0.1861
... A142: ='Metales puros'!B143 -> 1700 | B142: ='Metales puros'!H143 -> 0.31648184 | C142: ='Metales puros'!I143 -> 12.370536 | D142: ='Metales puros'!M143 -> 0.19853159 | E142: ='Metales puros'!N143 -> 12.70352 | F142: ='Metales puros'!R143 -> 2.2048986 | G142: ='Metales puros'!S143 -> 7.1880858 | H142: ='Metales puros'!W143 -> 0.25589485 | I142: ='Metales puros'!X143 -> 12.026034 | J142: ='Metales puros'!AB143 -> 0.6273 | K142: ='Metales puros'!AC143 -> 3.7605 | L142: ='Metales puros'!AG143 -> 0.6794 | M142: ='Metales puros'!AH143 -> 4.0209 | N142: ='Metales puros'!AL143 -> 1.0197 | O142: ='Metales puros'!AM143 -> 4.4072
